2021-02-17 05:02:15,945 - instabot version: 0.117.0 (bot /usr/local/lib/python3.8/dist-packages/instabot-0.117.0-py3.8.egg/instabot/bot/bot.py:279) - INFO - Instabot version: 0.117.0 Started
2021-02-17 05:02:15,946 - instabot version: 0.117.0 (bot /usr/local/lib/python3.8/dist-packages/instabot-0.117.0-py3.8.egg/instabot/bot/bot.py:280) - DEBUG - Bot imported from /usr/local/lib/python3.8/dist-packages/instabot-0.117.0-py3.8.egg/instabot/bot/bot.py
2021-02-17 05:02:15,947 - instabot version: 0.117.0 (api_login /usr/local/lib/python3.8/dist-packages/instabot-0.117.0-py3.8.egg/instabot/api/api_login.py:116) - INFO - Not yet logged in starting: PRE-LOGIN FLOW!
2021-02-17 05:02:16,749 - instabot version: 0.117.0 (api /usr/local/lib/python3.8/dist-packages/instabot-0.117.0-py3.8.egg/instabot/api/api.py:546) - DEBUG - POST to endpoint: accounts/contact_point_prefill/ returned response: <Response [200]>
2021-02-17 05:02:17,361 - instabot version: 0.117.0 (api /usr/local/lib/python3.8/dist-packages/instabot-0.117.0-py3.8.egg/instabot/api/api.py:546) - DEBUG - POST to endpoint: qe/sync/ returned response: <Response [200]>
2021-02-17 05:02:18,182 - instabot version: 0.117.0 (api /usr/local/lib/python3.8/dist-packages/instabot-0.117.0-py3.8.egg/instabot/api/api.py:546) - DEBUG - POST to endpoint: launcher/sync/ returned response: <Response [200]>
2021-02-17 05:02:19,000 - instabot version: 0.117.0 (api /usr/local/lib/python3.8/dist-packages/instabot-0.117.0-py3.8.egg/instabot/api/api.py:546) - DEBUG - POST to endpoint: accounts/get_prefill_candidates/ returned response: <Response [200]>
2021-02-17 05:02:20,844 - instabot version: 0.117.0 (api /usr/local/lib/python3.8/dist-packages/instabot-0.117.0-py3.8.egg/instabot/api/api.py:546) - DEBUG - POST to endpoint: accounts/login/ returned response: <Response [400]>
2021-02-17 05:02:20,846 - instabot version: 0.117.0 (api /usr/local/lib/python3.8/dist-packages/instabot-0.117.0-py3.8.egg/instabot/api/api.py:561) - DEBUG - Responsecode indicates error; response content: b'{"message":"You can log in with your linked Facebook account.","invalid_credentials":true,"error_title":"Forgotten password for bow.wie.902?","buttons":[{"title":"Try Again","action":"dismiss"},{"title":"Use Facebook","action":"login_with_facebook"}],"status":"fail","error_type":"bad_password"}'
2021-02-17 05:02:20,846 - instabot version: 0.117.0 (api /usr/local/lib/python3.8/dist-packages/instabot-0.117.0-py3.8.egg/instabot/api/api.py:567) - ERROR - Request returns 400 error!
2021-02-17 05:02:20,846 - instabot version: 0.117.0 (api /usr/local/lib/python3.8/dist-packages/instabot-0.117.0-py3.8.egg/instabot/api/api.py:644) - INFO - Instagram's error message: You can log in with your linked Facebook account.
2021-02-17 05:02:20,847 - instabot version: 0.117.0 (api /usr/local/lib/python3.8/dist-packages/instabot-0.117.0-py3.8.egg/instabot/api/api.py:647) - INFO - Error type: bad_password
2021-02-17 05:02:20,847 - instabot version: 0.117.0 (api /usr/local/lib/python3.8/dist-packages/instabot-0.117.0-py3.8.egg/instabot/api/api.py:365) - ERROR - Failed to login go to instagram and change your password
2021-02-17 05:02:20,847 - instabot version: 0.117.0 (api /usr/local/lib/python3.8/dist-packages/instabot-0.117.0-py3.8.egg/instabot/api/api.py:418) - INFO - Username or password is incorrect.
